<?xml version="1.0" encoding="UTF-8"?>
<!-- Generated by org.testng.reporters.JUnitReportReporter -->
<testsuite hostname="BDC4-D-5RK2RG2" name="testng1.Tests" tests="3" failures="0" timestamp="4 Jul 2019 07:04:56 GMT" time="0.011" errors="3">
  <testcase name="failTest" time="0.008" classname="testng1.Tests">
    <error type="java.lang.RuntimeException">
      <![CDATA[java.lang.RuntimeException
	at org.testng.internal.TestResult.toString(TestResult.java:245)
	at org.testng.internal.TestResult.toString(TestResult.java:226)
	at org.testng.remote.strprotocol.TestResultMessage.toString(TestResultMessage.java:330)
	at org.testng.remote.strprotocol.TestResultMessage.<init>(TestResultMessage.java:106)
	at org.testng.remote.strprotocol.TestResultMessage.<init>(TestResultMessage.java:124)
	at org.testng.remote.strprotocol.RemoteTestListener.onTestFailure(RemoteTestListener.java:72)
	at org.testng.remote.strprotocol.RemoteTestListener.onConfigurationFailure(RemoteTestListener.java:102)
	at org.testng.internal.Invoker.runConfigurationListeners(Invoker.java:1774)
	at org.testng.internal.Invoker.handleConfigurationFailure(Invoker.java:307)
	at org.testng.internal.Invoker.invokeConfigurations(Invoker.java:237)
	at org.testng.internal.Invoker.invokeMethod(Invoker.java:605)
	at org.testng.internal.Invoker.invokeTestMethod(Invoker.java:849)
	at org.testng.internal.Invoker.invokeTestMethods(Invoker.java:1157)
	at org.testng.internal.TestMethodWorker.invokeTestMethods(TestMethodWorker.java:124)
	at org.testng.internal.TestMethodWorker.run(TestMethodWorker.java:108)
	at org.testng.TestRunner.privateRun(TestRunner.java:771)
	at org.testng.TestRunner.run(TestRunner.java:621)
	at org.testng.SuiteRunner.runTest(SuiteRunner.java:357)
	at org.testng.SuiteRunner.runSequentially(SuiteRunner.java:352)
	at org.testng.SuiteRunner.privateRun(SuiteRunner.java:310)
	at org.testng.SuiteRunner.run(SuiteRunner.java:259)
	at org.testng.SuiteRunnerWorker.runSuite(SuiteRunnerWorker.java:52)
	at org.testng.SuiteRunnerWorker.run(SuiteRunnerWorker.java:86)
	at org.testng.TestNG.runSuitesSequentially(TestNG.java:1200)
	at org.testng.TestNG.runSuitesLocally(TestNG.java:1125)
	at org.testng.TestNG.run(TestNG.java:1033)
	at org.testng.remote.RemoteTestNG.run(RemoteTestNG.java:111)
	at org.testng.remote.RemoteTestNG.initAndRun(RemoteTestNG.java:204)
	at org.testng.remote.RemoteTestNG.main(RemoteTestNG.java:175)
]]>
    </error>
  </testcase> <!-- failTest -->
  <testcase name="passTest" time="0.002" classname="testng1.Tests">
    <error type="java.lang.RuntimeException">
      <![CDATA[java.lang.RuntimeException
	at org.testng.internal.TestResult.toString(TestResult.java:245)
	at org.testng.internal.TestResult.toString(TestResult.java:226)
	at org.testng.remote.strprotocol.TestResultMessage.toString(TestResultMessage.java:330)
	at org.testng.remote.strprotocol.TestResultMessage.<init>(TestResultMessage.java:106)
	at org.testng.remote.strprotocol.TestResultMessage.<init>(TestResultMessage.java:124)
	at org.testng.remote.strprotocol.RemoteTestListener.onTestFailure(RemoteTestListener.java:72)
	at org.testng.remote.strprotocol.RemoteTestListener.onConfigurationFailure(RemoteTestListener.java:102)
	at org.testng.internal.Invoker.runConfigurationListeners(Invoker.java:1774)
	at org.testng.internal.Invoker.handleConfigurationFailure(Invoker.java:307)
	at org.testng.internal.Invoker.invokeConfigurations(Invoker.java:237)
	at org.testng.internal.Invoker.invokeMethod(Invoker.java:605)
	at org.testng.internal.Invoker.invokeTestMethod(Invoker.java:849)
	at org.testng.internal.Invoker.invokeTestMethods(Invoker.java:1157)
	at org.testng.internal.TestMethodWorker.invokeTestMethods(TestMethodWorker.java:124)
	at org.testng.internal.TestMethodWorker.run(TestMethodWorker.java:108)
	at org.testng.TestRunner.privateRun(TestRunner.java:771)
	at org.testng.TestRunner.run(TestRunner.java:621)
	at org.testng.SuiteRunner.runTest(SuiteRunner.java:357)
	at org.testng.SuiteRunner.runSequentially(SuiteRunner.java:352)
	at org.testng.SuiteRunner.privateRun(SuiteRunner.java:310)
	at org.testng.SuiteRunner.run(SuiteRunner.java:259)
	at org.testng.SuiteRunnerWorker.runSuite(SuiteRunnerWorker.java:52)
	at org.testng.SuiteRunnerWorker.run(SuiteRunnerWorker.java:86)
	at org.testng.TestNG.runSuitesSequentially(TestNG.java:1200)
	at org.testng.TestNG.runSuitesLocally(TestNG.java:1125)
	at org.testng.TestNG.run(TestNG.java:1033)
	at org.testng.remote.RemoteTestNG.run(RemoteTestNG.java:111)
	at org.testng.remote.RemoteTestNG.initAndRun(RemoteTestNG.java:204)
	at org.testng.remote.RemoteTestNG.main(RemoteTestNG.java:175)
]]>
    </error>
  </testcase> <!-- passTest -->
  <testcase name="skipTest" time="0.001" classname="testng1.Tests">
    <error type="java.lang.RuntimeException">
      <![CDATA[java.lang.RuntimeException
	at org.testng.internal.TestResult.toString(TestResult.java:245)
	at org.testng.internal.TestResult.toString(TestResult.java:226)
	at org.testng.remote.strprotocol.TestResultMessage.toString(TestResultMessage.java:330)
	at org.testng.remote.strprotocol.TestResultMessage.<init>(TestResultMessage.java:106)
	at org.testng.remote.strprotocol.TestResultMessage.<init>(TestResultMessage.java:124)
	at org.testng.remote.strprotocol.RemoteTestListener.onTestFailure(RemoteTestListener.java:72)
	at org.testng.remote.strprotocol.RemoteTestListener.onConfigurationFailure(RemoteTestListener.java:102)
	at org.testng.internal.Invoker.runConfigurationListeners(Invoker.java:1774)
	at org.testng.internal.Invoker.handleConfigurationFailure(Invoker.java:307)
	at org.testng.internal.Invoker.invokeConfigurations(Invoker.java:237)
	at org.testng.internal.Invoker.invokeMethod(Invoker.java:605)
	at org.testng.internal.Invoker.invokeTestMethod(Invoker.java:849)
	at org.testng.internal.Invoker.invokeTestMethods(Invoker.java:1157)
	at org.testng.internal.TestMethodWorker.invokeTestMethods(TestMethodWorker.java:124)
	at org.testng.internal.TestMethodWorker.run(TestMethodWorker.java:108)
	at org.testng.TestRunner.privateRun(TestRunner.java:771)
	at org.testng.TestRunner.run(TestRunner.java:621)
	at org.testng.SuiteRunner.runTest(SuiteRunner.java:357)
	at org.testng.SuiteRunner.runSequentially(SuiteRunner.java:352)
	at org.testng.SuiteRunner.privateRun(SuiteRunner.java:310)
	at org.testng.SuiteRunner.run(SuiteRunner.java:259)
	at org.testng.SuiteRunnerWorker.runSuite(SuiteRunnerWorker.java:52)
	at org.testng.SuiteRunnerWorker.run(SuiteRunnerWorker.java:86)
	at org.testng.TestNG.runSuitesSequentially(TestNG.java:1200)
	at org.testng.TestNG.runSuitesLocally(TestNG.java:1125)
	at org.testng.TestNG.run(TestNG.java:1033)
	at org.testng.remote.RemoteTestNG.run(RemoteTestNG.java:111)
	at org.testng.remote.RemoteTestNG.initAndRun(RemoteTestNG.java:204)
	at org.testng.remote.RemoteTestNG.main(RemoteTestNG.java:175)
]]>
    </error>
  </testcase> <!-- skipTest -->
</testsuite> <!-- testng1.Tests -->
